Workbook

Sheet TOTAL
A1: Planificación Total
A2: Total (sin documentacion) | B2: 2026
A3: Escenario | B3: julio | C3: agosto | D3: septiembre | E3: Total
A4: Leads | B4: ='Por Programa'!B68 -> 143 | C4: ='Por Programa'!C68 -> 118 | D4: ='Por Programa'!D68 -> 401 | E4: =SUM(B4:D4) -> 662
A5: MKT Presu. | B5: ='Por Programa'!B69 -> 8700 | C5: ='Por Programa'!C69 -> 7176.5674 | D5: ='Por Programa'!D69 -> 24220.915 | E5: =SUM(B5:D5) -> 40097.483
A6: CPL | B6: =B5/B4 -> 60.839161 | C6: =C5/C4 -> 60.818368 | D6: =D5/D4 -> 60.401285 | E6: =E5/E4 -> 60.570216
A7: Ventas Netas totales | B7: ='Por Programa'!B71 -> 5 | C7: ='Por Programa'!C71 -> 6 | D7: ='Por Programa'!D71 -> 33 | E7: =SUM(B7:D7) -> 44
A8: Tasa de Conversión | B8: =B7/B4 -> 0.034965035 | C8: =C7/C4 -> 0.050847458 | D8: =D7/D4 -> 0.082294264 | E8: =E7/E4 -> 0.066465257
A9: Facturación Neta | B9: ='Por Programa'!B73 -> 19000 | C9: ='Por Programa'!C73 -> 19950 | D9: ='Por Programa'!D73 -> 96050 | E9: =SUM(B9:D9) -> 135000
A10: GP | B10: =(B9-B5)/B9 -> 0.54210526 | C10: =(C9-C5)/C9 -> 0.64027231 | D10: =(D9-D5)/D9 -> 0.74783014 | E10: =(E9-E5)/E9 -> 0.70298161
A12: Leads diarios | B12: =ROUND(B4/20,0) -> 7 | C12: =ROUND(C4/30,0) -> 4 | D12: =ROUND(D4/30,0) -> 13

Sheet Por Programa
A1: UVIC-UCC · KPIs v3 POR PROGRAMA
A3: Postgrau Comunicació Científica | B3: 2026
A4: Escenario | B4: julio | C4: agosto | D4: septiembre | E4: Total
A5: Leads | B5: =ROUND(B6/B7,0) -> 42 | C5: =ROUND(C6/C7,0) -> 17 | D5: =ROUND(D6/D7,0) -> 59 | E5: =SUM(B5:D5) -> 118
A6: MKT Presu. | B6: 2300 | C6: 955.1817 | D6: 3223.7384 | E6: =SUM(B6:D6) -> 6478.9201
A7: CPL | B7: 55 | C7: 55 | D7: 55 | E7: =E6/E5 -> 54.906103
A8: Ventas Netas totales | B8: =ROUND(B5*B9,0) -> 1 | C8: =ROUND(C5*C9,0) -> 1 | D8: =ROUND(D5*D9,0) -> 5 | E8: 6
A9: Tasa de Conversión | B9: 0.0345 | C9: 0.0432 | D9: 0.0768 | E9: 0.0614
A10: Facturación Neta | B10: ='Datos-Nuevos'!$B$4*B8 -> 3300 | C10: ='Datos-Nuevos'!$B$4*C8 -> 3300 | D10: ='Datos-Nuevos'!$B$4*D8 -> 16500 | E10: =SUM(B10:D10) -> 23100
A11: GP | B11: =(B10-B6)/B10 -> 0.3030303 | C11: =(C10-C6)/C10 -> 0.710551 | D11: =(D10-D6)/D10 -> 0.80462192 | E11: =(E10-E6)/E10 -> 0.71952727
A13: Leads diarios | B13: =ROUND(B5/20,0) -> 2 | C13: =ROUND(C5/30,0) -> 1 | D13: =ROUND(D5/30,0) -> 2
A15: Màster Gestió i Màrqueting Esportiu | B15: 2026
A16: Escenario | B16: julio | C16: agosto | D16: septiembre | E16: Total
A17: Leads | B17: =ROUND(B18/B19,0) -> 31 | C17: =ROUND(C18/C19,0) -> 24 | D17: =ROUND(D18/D19,0) -> 82 | E17: =SUM(B17:D17) -> 137
A18: MKT Presu. | B18: 2000 | C18: 1573.4619 | D18: 5310.4341 | E18: =SUM(B18:D18) -> 8883.896
A19: CPL | B19: 65 | C19: 65 | D19: 65 | E19: =E18/E17 -> 64.845956
A20: Ventas Netas totales | B20: =ROUND(B17*B21,0) -> 1 | C20: =ROUND(C17*C21,0) -> 1 | D20: =ROUND(D17*D21,0) -> 5 | E20: =ROUND(E17*E21,0) -> 6
A21: Tasa de Conversión | B21: 0.0248 | C21: 0.031 | D21: 0.0551 | E21: 0.0441
A22: Facturación Neta | B22: ='Datos-Nuevos'!$B$5*B20 -> 6300 | C22: ='Datos-Nuevos'!$B$5*C20 -> 6300 | D22: ='Datos-Nuevos'!$B$5*D20 -> 31500 | E22: =SUM(B22:D22) -> 44100
A23: GP | B23: =(B22-B18)/B22 -> 0.68253968 | C23: =(C22-C18)/C22 -> 0.75024414 | D23: =(D22-D18)/D22 -> 0.83141479 | E23: =(E22-E18)/E22 -> 0.79855111
A25: Leads diarios | B25: =ROUND(B17/20,0) -> 2 | C25: =ROUND(C17/30,0) -> 1 | D25: =ROUND(D17/30,0) -> 3
A27: Executive MBA | B27: 2026
A28: Escenario | B28: julio | C28: agosto | D28: septiembre | E28: Total
A29: Leads | B29: =ROUND(B30/B31,0) -> 34 | C29: =ROUND(C30/C31,0) -> 28 | D29: =ROUND(D30/D31,0) -> 94 | E29: =SUM(B29:D29) -> 156
A30: MKT Presu. | B30: 2400 | C30: 1942.3597 | D30: 6555.4641 | E30: =SUM(B30:D30) -> 10897.824
A31: CPL | B31: 70 | C31: 70 | D31: 70 | E31: =E30/E29 -> 69.857845
A32: Ventas Netas totales | B32: =ROUND(B29*B33,0) -> 1 | C32: =ROUND(C29*C33,0) -> 1 | D32: =ROUND(D29*D33,0) -> 4 | E32: =SUM(B32:D32) -> 6
A33: Tasa de Conversión | B33: 0.018 | C33: 0.0225 | D33: 0.04 | E33: 0.032
A34: Facturación Neta | B34: ='Datos-Nuevos'!$B$6*B32 -> 7500 | C34: ='Datos-Nuevos'!$B$6*C32 -> 7500 | D34: ='Datos-Nuevos'!$B$6*D32 -> 30000 | E34: =SUM(B34:D34) -> 45000
A35: GP | B35: =(B34-B30)/B34 -> 0.68 | C35: =(C34-C30)/C34 -> 0.74101871 | D35: =(D34-D30)/D34 -> 0.78148453 | E35: =(E34-E30)/E34 -> 0.75782614
A37: Leads diarios | B37: =ROUND(B29/20,0) -> 2 | C37: =ROUND(C29/30,0) -> 1 | D37: =ROUND(D29/30,0) -> 3
A39: Postgrau Documental Social | B39: 2026
A40: Escenario | B40: julio | C40: agosto | D40: septiembre | E40: Total
A41: Leads | B41: =ROUND(B42/B43,0) -> 26 | C41: =ROUND(C42/C43,0) -> 16 | D41: =ROUND(D42/D43,0) -> 56 | E41: =SUM(B41:D41) -> 98
A42: MKT Presu. | B42: 1300 | C42: 823.4325 | D42: 2779.0848 | E42: =SUM(B42:D42) -> 4902.5173
A43: CPL | B43: 50 | C43: 50 | D43: 50 | E43: =E42/E41 -> 50.025687
A44: Ventas Netas totales | B44: =ROUND(B41*B45,0) -> 1 | C44: =ROUND(C41*C45,0) -> 1 | D44: =ROUND(D41*D45,0) -> 5 | E44: =SUM(B44:D44) -> 7
A45: Tasa de Conversión | B45: 0.0364 | C45: 0.0455 | D45: 0.081 | E45: 0.0648
A46: Facturación Neta | B46: 2137.5 | C46: 2137.5 | D46: 12825 | E46: =SUM(B46:D46) -> 17100
A47: GP | B47: =(B46-B42)/B46 -> 0.39181287 | C47: =(C46-C42)/C46 -> 0.61476842 | D47: =(D46-D42)/D46 -> 0.78330723 | E47: =(E46-E42)/E46 -> 0.71330308
...

Sheet Por Plataforma
A1: UVIC-UCC · KPIs v3 POR PLATAFORMA
A4: Meta Ads | B4: 2026
A5: Escenario | B5: julio | C5: agosto | D5: septiembre | E5: Total
A6: Leads | B6: =ROUND(B7/B8,0) -> 95 | C6: =ROUND(C7/C8,0) -> 86 | D6: =ROUND(D7/D8,0) -> 381 | E6: =SUM(B6:D6) -> 562
A7: MKT Presu. | B7: 5220 | C7: 4305.94 | D7: 13321.5 | E7: =SUM(B7:D7) -> 22847.44
A8: CPL | B8: 55 | C8: 50 | D8: 35 | E8: =E7/E6 -> 40.653808
A9: Ventas Netas totales | B9: =ROUND(B6*B10,0) -> 4 | C9: =ROUND(C6*C10,0) -> 2 | D9: =ROUND(D6*D10,0) -> 20 | E9: =SUM(B9:D9) -> 26
A10: Tasa de Conversión | B10: 0.0385 | C10: 0.028 | D10: 0.053 | E10: =E9/E6 -> 0.046263345
A12: Leads diarios | B12: =ROUND(B6/20,0) -> 5 | C12: =ROUND(C6/30,0) -> 3 | D12: =ROUND(D6/30,0) -> 13
A14: Google Ads | B14: 2026
A15: Escenario | B15: julio | C15: agosto | D15: septiembre | E15: Total
A16: Leads | B16: =ROUND(B17/B18,0) -> 48 | C16: =ROUND(C17/C18,0) -> 44 | D16: =ROUND(D17/D18,0) -> 198 | E16: =SUM(B16:D16) -> 290
A17: MKT Presu. | B17: 3480 | C17: 2870.63 | D17: 10899.41 | E17: =SUM(B17:D17) -> 17250.04
A18: CPL | B18: 73 | C18: 65 | D18: 55 | E18: =E17/E16 -> 59.482897
A19: Ventas Netas totales | B19: =ROUND(B16*B20,0) -> 1 | C19: =ROUND(C16*C20,0) -> 2 | D19: =ROUND(D16*D20,0) -> 13 | E19: =SUM(B19:D19) -> 16
A20: Tasa de Conversión | B20: 0.0265 | C20: 0.04 | D20: 0.065 | E20: =E19/E16 -> 0.055172414
A22: Leads diarios | B22: =ROUND(B16/20,0) -> 2 | C22: =ROUND(C16/30,0) -> 1 | D22: =ROUND(D16/30,0) -> 7

Sheet Datos-Nuevos
A1: DATOS DE PARTIDA v3 (celdas en azul = editables)
A2: Solo Catalunya · CPL real actual ≈ 98 € · plan a 50-70 €. Inversión y matrículas = TOTAL del trimestre.
A3: Programa | B3: Precio (€) | C3: CPL (€) | D3: Inversión TRIM (€) | E3: Meta % | F3: Google % | G3: Leads (trim) | H3: Matrículas (trim) | I3: Conv. efectiva | J3: Facturación (trim) (€) | K3: Opcional
A4: Postgrau Comunicació Científica | B4: 3300 | C4: 55 | D4: 5372.8973 | E4: 0.6 | F4: 0.4 | G4: 97.689 | H4: 6 | I4: 0.0614 | J4: 19800 | K4: No
A5: Màster Gestió i Màrqueting Esportiu | B5: 6300 | C5: 65 | D5: 8850.7234 | E5: 0.625 | F5: 0.375 | G5: 136.165 | H5: 6 | I5: 0.0441 | J5: 37800 | K5: No
A6: Executive MBA | B6: 7500 | C6: 70 | D6: 10925.773 | E6: 0.5833 | F6: 0.4167 | G6: 156.0825 | H6: 5 | I6: 0.032 | J6: 37500 | K6: No
A7: Plus Executive (Lideratge IA) | B7: 950 | C7: 55 | D7: 15218.798 | E7: 0.65 | F7: 0.35 | G7: 276.7054 | H7: 25 | I7: 0.0903 | J7: 23750 | K7: Sí
A8: TOTAL 5 prog. | D8: =SUM(D4:D7) -> 40368.192 | G8: 759.2781 | H8: 48 | I8: 0.0632 | J8: 135950
A11: Perfil mensual de INVERSIÓN (€ · editable)
A12: Julio | B12: 10000 | C12: =B12/$B$15 -> 0.22222222
A13: Agosto | B13: 8000 | C13: =B13/$B$15 -> 0.17777778
A14: Septiembre | B14: 27000 | C14: =B14/$B$15 -> 0.6
A15: Total | B15: 45000 | F15: =17000*3 -> 51000
A16: Consumido a 15-jul: 3100 € · pendiente julio: 6900 €
A18: Perfil mensual de MATRÍCULAS (conteo · editable)
A19: Julio | B19: 5 | C19: =B19/$B$22 -> 0.12195122
A20: Agosto | B20: 6 | C20: =B20/$B$22 -> 0.14634146
A21: Septiembre | B21: 30 | C21: =B21/$B$22 -> 0.73170732
A22: Total | B22: =SUM(B19:B21) -> 41 | C22: =B22/$B$22 -> 1
